<?xml version="1.0"?>
<robot name="mobilerobot" xmlns:xacro="http://ros.org/wiki/xacro">

	<xacro:property name="wheel_width" value="0.05" />
	<xacro:property name="wheel_radius" value="0.1" />
	<xacro:property name="wheel_separation" value="0.35" />
	<xacro:property name="base_frame_width" value="0.3" />
	<xacro:property name="base_frame_length" value="0.3" />
	<xacro:property name="base_frame_height" value="0.05" />
	<xacro:property name="pi" value="3.1415" />

	<material name="black">
		<color rgba="0 0 0 1"/>
	</material>

	<material name="white">
		<color rgba="1 1 1 1"/>
	</material>

	<xacro:macro name="rec_inertial" params="mass">
		<inertial>
			<mass value="${mass}" />
			<inertia ixx="0.0346875" ixy="0.0" ixz="0.0" iyy="0.0346875" iyz="0.0" izz="0.0675" />
		</inertial>
	</xacro:macro>

	<xacro:macro name="cir_inertial" params="mass">
		<inertial>
			<mass value="${mass}" />
			<inertia ixx="0.00425424005" ixy="0.0" ixz="0.0" iyy="0.00425424005" iyz="0.0" izz="0.00785398163" />
		</inertial>
	</xacro:macro>


	<xacro:macro name="wheel" params="prefix reflect">
		<link name="${prefix}_wheel">
			<visual>
				<origin xyz="0 0 0" rpy="0 ${pi/2} 0"/>
				<geometry>
					<cylinder radius="${wheel_radius}" length="${wheel_width}"/>
				</geometry>
				<material name="black"/>
			</visual>
			<collision>
				<origin xyz="0 0 0" rpy="0 ${pi/2} 0"/>
				<geometry>
					<cylinder radius="${wheel_radius}" length="${wheel_width}"/>
				</geometry>
				<surface>
					<friction>
						<torsional>
							<coefficient>1</coefficient>
						</torsional>
					</friction>
				</surface>
			</collision>
			<xacro:cir_inertial mass="${300 * pi * wheel_radius * wheel_radius * wheel_width}"/>
		</link>
		<joint name="base_to_${prefix}_wheel_joint" type="continuous">
			<parent link="base_link"/>
			<child link="${prefix}_wheel"/>
			<axis xyz="1 0 0" rpy="0 0 0"/>
			<origin xyz="${wheel_separation*reflect/2} 0 0"/>
			<dynamics damping="0"/>
		</joint>

		<gazebo reference="${prefix}_wheel">
			<mu1 value="1"/>
			<mu2 value="0.7"/>
			<material>Gazebo/Blue</material>
		</gazebo>

		<transmission name="${prefix}_wheel_trans">
			<type>transmission_interface/SimpleTransmission</type>
			<joint name="base_to_${prefix}_wheel_joint">
				<hardwareInterface>hardware_interface/VelocityJointInterface</hardwareInterface>
			</joint>
			<actuator name="${prefix}_wheel_motor">
				<mechanicalReduction>1</mechanicalReduction>
				<hardwareInterface>VelocityJointInterface</hardwareInterface>
			</actuator>
		</transmission>
	</xacro:macro>

	<link name="base_link">
		<visual>
			<geometry>
				<box size="${base_frame_width} ${base_frame_length} ${base_frame_height}"/>
			</geometry>
			<material name="white"/>
		</visual>
		<collision>
			<geometry>
				<box size="${base_frame_width} ${base_frame_length} ${base_frame_height}"/>
			</geometry>
			<surface>
				<friction>
					<torsional>
						<coefficient>1</coefficient>
					</torsional>
				</friction>
			</surface>
		</collision>
		<xacro:rec_inertial mass="${8050 * base_frame_width * base_frame_length * base_frame_height}"/>
	</link>

	<xacro:wheel prefix="right" reflect="1"/>
	<xacro:wheel prefix="left" reflect="-1"/>

	<gazebo reference='base_link'>
		<mu1 value="0.7"/>
		<mu2 value="0.4"/>
		<material>Gazebo/White</material>
	</gazebo>

	<gazebo>
		<plugin name="gazebo_ros_control" filename="libgazebo_ros_control.so">
			<robotSimType>gazebo_ros_control/DefaultRobotHWSim</robotSimType>
			<legacyModeNS>true</legacyModeNS>
		</plugin>
	</gazebo>
</robot>
